2022-08-03 02:35:20,934 ERROR Exception on / [GET] [in /home/smr/Desktop/new/flask-grinberg/venv/lib/python3.8/site-packages/flask/app.py:1449]
Traceback (most recent call last):
  File "/home/smr/Desktop/new/flask-grinberg/venv/lib/python3.8/site-packages/sqlalchemy/engine/base.py", line 1819, in _execute_context
    self.dialect.do_execute(
  File "/home/smr/Desktop/new/flask-grinberg/venv/lib/python3.8/site-packages/sqlalchemy/engine/default.py", line 732, in do_execute
    cursor.execute(statement, parameters)
sqlite3.OperationalError: database is locked

The above exception was the direct cause of the following exception:

Traceback (most recent call last):
  File "/home/smr/Desktop/new/flask-grinberg/venv/lib/python3.8/site-packages/flask/app.py", line 2073, in wsgi_app
    response = self.full_dispatch_request()
  File "/home/smr/Desktop/new/flask-grinberg/venv/lib/python3.8/site-packages/flask/app.py", line 1519, in full_dispatch_request
    rv = self.handle_user_exception(e)
  File "/home/smr/Desktop/new/flask-grinberg/venv/lib/python3.8/site-packages/flask/app.py", line 1515, in full_dispatch_request
    rv = self.preprocess_request()
  File "/home/smr/Desktop/new/flask-grinberg/venv/lib/python3.8/site-packages/flask/app.py", line 1857, in preprocess_request
    rv = self.ensure_sync(before_func)()
  File "/home/smr/Desktop/new/flask-grinberg/myapp/routes.py", line 15, in before_request_handler
    db.session.commit()
  File "<string>", line 2, in commit
  File "/home/smr/Desktop/new/flask-grinberg/venv/lib/python3.8/site-packages/sqlalchemy/orm/session.py", line 1451, in commit
    self._transaction.commit(_to_root=self.future)
  File "/home/smr/Desktop/new/flask-grinberg/venv/lib/python3.8/site-packages/sqlalchemy/orm/session.py", line 829, in commit
    self._prepare_impl()
  File "/home/smr/Desktop/new/flask-grinberg/venv/lib/python3.8/site-packages/sqlalchemy/orm/session.py", line 808, in _prepare_impl
    self.session.flush()
  File "/home/smr/Desktop/new/flask-grinberg/venv/lib/python3.8/site-packages/sqlalchemy/orm/session.py", line 3383, in flush
    self._flush(objects)
  File "/home/smr/Desktop/new/flask-grinberg/venv/lib/python3.8/site-packages/sqlalchemy/orm/session.py", line 3523, in _flush
    transaction.rollback(_capture_exception=True)
  File "/home/smr/Desktop/new/flask-grinberg/venv/lib/python3.8/site-packages/sqlalchemy/util/langhelpers.py", line 70, in __exit__
    compat.raise_(
  File "/home/smr/Desktop/new/flask-grinberg/venv/lib/python3.8/site-packages/sqlalchemy/util/compat.py", line 208, in raise_
    raise exception
  File "/home/smr/Desktop/new/flask-grinberg/venv/lib/python3.8/site-packages/sqlalchemy/orm/session.py", line 3483, in _flush
    flush_context.execute()
  File "/home/smr/Desktop/new/flask-grinberg/venv/lib/python3.8/site-packages/sqlalchemy/orm/unitofwork.py", line 456, in execute
    rec.execute(self)
  File "/home/smr/Desktop/new/flask-grinberg/venv/lib/python3.8/site-packages/sqlalchemy/orm/unitofwork.py", line 630, in execute
    util.preloaded.orm_persistence.save_obj(
  File "/home/smr/Desktop/new/flask-grinberg/venv/lib/python3.8/site-packages/sqlalchemy/orm/persistence.py", line 237, in save_obj
    _emit_update_statements(
  File "/home/smr/Desktop/new/flask-grinberg/venv/lib/python3.8/site-packages/sqlalchemy/orm/persistence.py", line 1001, in _emit_update_statements
    c = connection._execute_20(
  File "/home/smr/Desktop/new/flask-grinberg/venv/lib/python3.8/site-packages/sqlalchemy/engine/base.py", line 1631, in _execute_20
    return meth(self, args_10style, kwargs_10style, execution_options)
  File "/home/smr/Desktop/new/flask-grinberg/venv/lib/python3.8/site-packages/sqlalchemy/sql/elements.py", line 332, in _execute_on_connection
    return connection._execute_clauseelement(
  File "/home/smr/Desktop/new/flask-grinberg/venv/lib/python3.8/site-packages/sqlalchemy/engine/base.py", line 1498, in _execute_clauseelement
    ret = self._execute_context(
  File "/home/smr/Desktop/new/flask-grinberg/venv/lib/python3.8/site-packages/sqlalchemy/engine/base.py", line 1862, in _execute_context
    self._handle_dbapi_exception(
  File "/home/smr/Desktop/new/flask-grinberg/venv/lib/python3.8/site-packages/sqlalchemy/engine/base.py", line 2043, in _handle_dbapi_exception
    util.raise_(
  File "/home/smr/Desktop/new/flask-grinberg/venv/lib/python3.8/site-packages/sqlalchemy/util/compat.py", line 208, in raise_
    raise exception
  File "/home/smr/Desktop/new/flask-grinberg/venv/lib/python3.8/site-packages/sqlalchemy/engine/base.py", line 1819, in _execute_context
    self.dialect.do_execute(
  File "/home/smr/Desktop/new/flask-grinberg/venv/lib/python3.8/site-packages/sqlalchemy/engine/default.py", line 732, in do_execute
    cursor.execute(statement, parameters)
sqlalchemy.exc.OperationalError: (sqlite3.OperationalError) database is locked
[SQL: UPDATE user SET last_seen=? WHERE user.id = ?]
[parameters: ('2022-08-02 22:05:15.916749', 1)]
(Background on this error at: https://sqlalche.me/e/14/e3q8)
2022-08-03 02:42:49,599 INFO Microblog startup [in /home/smr/Desktop/new/flask-grinberg/myapp/logger.py:61]
