2022-07-31 23:38:32,761 ERROR Exception on /follow/mohammad [GET] [in C:\Users\SMR\Desktop\flask-grinberg\flask-grinberg\venv\lib\site-packages\flask\app.py:1449]
Traceback (most recent call last):
  File "C:\Users\SMR\Desktop\flask-grinberg\flask-grinberg\venv\lib\site-packages\flask\app.py", line 2073, in wsgi_app
    response = self.full_dispatch_request()
  File "C:\Users\SMR\Desktop\flask-grinberg\flask-grinberg\venv\lib\site-packages\flask\app.py", line 1519, in full_dispatch_request
    rv = self.handle_user_exception(e)
  File "C:\Users\SMR\Desktop\flask-grinberg\flask-grinberg\venv\lib\site-packages\flask\app.py", line 1517, in full_dispatch_request
    rv = self.dispatch_request()
  File "C:\Users\SMR\Desktop\flask-grinberg\flask-grinberg\venv\lib\site-packages\flask\app.py", line 1503, in dispatch_request
    return self.ensure_sync(self.view_functions[rule.endpoint])(**req.view_args)
  File "C:\Users\SMR\Desktop\flask-grinberg\flask-grinberg\venv\lib\site-packages\flask_login\utils.py", line 290, in decorated_view
    return current_app.ensure_sync(func)(*args, **kwargs)
  File "C:\Users\SMR\Desktop\flask-grinberg\flask-grinberg\myapp\routes.py", line 129, in follow
    return redirect(url_for("user",username))
TypeError: url_for() takes 1 positional argument but 2 were given
2022-07-31 23:40:09,135 INFO Microblog startup [in C:\Users\SMR\Desktop\flask-grinberg\flask-grinberg\myapp\logger.py:61]
2022-07-31 23:40:49,043 ERROR Exception on /follow/ali [GET] [in C:\Users\SMR\Desktop\flask-grinberg\flask-grinberg\venv\lib\site-packages\flask\app.py:1449]
Traceback (most recent call last):
  File "C:\Users\SMR\Desktop\flask-grinberg\flask-grinberg\venv\lib\site-packages\flask\app.py", line 2073, in wsgi_app
    response = self.full_dispatch_request()
  File "C:\Users\SMR\Desktop\flask-grinberg\flask-grinberg\venv\lib\site-packages\flask\app.py", line 1519, in full_dispatch_request
    rv = self.handle_user_exception(e)
  File "C:\Users\SMR\Desktop\flask-grinberg\flask-grinberg\venv\lib\site-packages\flask\app.py", line 1517, in full_dispatch_request
    rv = self.dispatch_request()
  File "C:\Users\SMR\Desktop\flask-grinberg\flask-grinberg\venv\lib\site-packages\flask\app.py", line 1503, in dispatch_request
    return self.ensure_sync(self.view_functions[rule.endpoint])(**req.view_args)
  File "C:\Users\SMR\Desktop\flask-grinberg\flask-grinberg\venv\lib\site-packages\flask_login\utils.py", line 290, in decorated_view
    return current_app.ensure_sync(func)(*args, **kwargs)
  File "C:\Users\SMR\Desktop\flask-grinberg\flask-grinberg\myapp\routes.py", line 129, in follow
    return redirect(url_for("user",username))
TypeError: url_for() takes 1 positional argument but 2 were given
2022-07-31 23:42:25,771 INFO Microblog startup [in C:\Users\SMR\Desktop\flask-grinberg\flask-grinberg\myapp\logger.py:61]
2022-07-31 23:42:35,449 ERROR Exception on /follow/ali [GET] [in C:\Users\SMR\Desktop\flask-grinberg\flask-grinberg\venv\lib\site-packages\flask\app.py:1449]
Traceback (most recent call last):
  File "C:\Users\SMR\Desktop\flask-grinberg\flask-grinberg\venv\lib\site-packages\flask\app.py", line 2073, in wsgi_app
    response = self.full_dispatch_request()
  File "C:\Users\SMR\Desktop\flask-grinberg\flask-grinberg\venv\lib\site-packages\flask\app.py", line 1519, in full_dispatch_request
    rv = self.handle_user_exception(e)
  File "C:\Users\SMR\Desktop\flask-grinberg\flask-grinberg\venv\lib\site-packages\flask\app.py", line 1517, in full_dispatch_request
    rv = self.dispatch_request()
  File "C:\Users\SMR\Desktop\flask-grinberg\flask-grinberg\venv\lib\site-packages\flask\app.py", line 1503, in dispatch_request
    return self.ensure_sync(self.view_functions[rule.endpoint])(**req.view_args)
  File "C:\Users\SMR\Desktop\flask-grinberg\flask-grinberg\venv\lib\site-packages\flask_login\utils.py", line 290, in decorated_view
    return current_app.ensure_sync(func)(*args, **kwargs)
  File "C:\Users\SMR\Desktop\flask-grinberg\flask-grinberg\myapp\routes.py", line 129, in follow
    return redirect(url_for("user",usernname = username))
  File "C:\Users\SMR\Desktop\flask-grinberg\flask-grinberg\venv\lib\site-packages\flask\helpers.py", line 336, in url_for
    return appctx.app.handle_url_build_error(error, endpoint, values)
  File "C:\Users\SMR\Desktop\flask-grinberg\flask-grinberg\venv\lib\site-packages\flask\helpers.py", line 323, in url_for
    rv = url_adapter.build(
  File "C:\Users\SMR\Desktop\flask-grinberg\flask-grinberg\venv\lib\site-packages\werkzeug\routing\map.py", line 917, in build
    raise BuildError(endpoint, values, method, self)
werkzeug.routing.exceptions.BuildError: Could not build url for endpoint 'user' with values ['usernname']. Did you forget to specify values ['username']?
2022-07-31 23:43:29,447 INFO Microblog startup [in C:\Users\SMR\Desktop\flask-grinberg\flask-grinberg\myapp\logger.py:61]
2022-07-31 23:44:21,230 INFO Microblog startup [in C:\Users\SMR\Desktop\flask-grinberg\flask-grinberg\myapp\logger.py:61]
2022-07-31 23:44:59,630 INFO Microblog startup [in C:\Users\SMR\Desktop\flask-grinberg\flask-grinberg\myapp\logger.py:61]
2022-07-31 23:46:20,047 INFO Microblog startup [in C:\Users\SMR\Desktop\flask-grinberg\flask-grinberg\myapp\logger.py:61]
2022-07-31 23:49:01,665 INFO Microblog startup [in C:\Users\SMR\Desktop\flask-grinberg\flask-grinberg\myapp\logger.py:61]
2022-07-31 23:49:25,966 INFO Microblog startup [in C:\Users\SMR\Desktop\flask-grinberg\flask-grinberg\myapp\logger.py:61]
2022-08-01 08:02:14,117 INFO Microblog startup [in C:\Users\SMR\Desktop\flask-grinberg\flask-grinberg\myapp\logger.py:61]
2022-08-01 08:39:49,386 INFO Microblog startup [in C:\Users\SMR\Desktop\flask-grinberg\flask-grinberg\myapp\logger.py:61]
2022-08-01 08:40:04,386 INFO Microblog startup [in C:\Users\SMR\Desktop\flask-grinberg\flask-grinberg\myapp\logger.py:61]
2022-08-01 08:40:19,011 INFO Microblog startup [in C:\Users\SMR\Desktop\flask-grinberg\flask-grinberg\myapp\logger.py:61]
2022-08-03 01:26:09,427 INFO Microblog startup [in /home/smr/Desktop/new/flask-grinberg/myapp/logger.py:61]
2022-08-03 02:13:19,489 INFO Microblog startup [in /home/smr/Desktop/new/flask-grinberg/myapp/logger.py:61]
2022-08-03 02:13:22,420 ERROR Exception on / [GET] [in /home/smr/Desktop/new/flask-grinberg/venv/lib/python3.8/site-packages/flask/app.py:1449]
Traceback (most recent call last):
  File "/home/smr/Desktop/new/flask-grinberg/venv/lib/python3.8/site-packages/flask/app.py", line 2073, in wsgi_app
    response = self.full_dispatch_request()
  File "/home/smr/Desktop/new/flask-grinberg/venv/lib/python3.8/site-packages/flask/app.py", line 1519, in full_dispatch_request
    rv = self.handle_user_exception(e)
  File "/home/smr/Desktop/new/flask-grinberg/venv/lib/python3.8/site-packages/flask/app.py", line 1517, in full_dispatch_request
    rv = self.dispatch_request()
  File "/home/smr/Desktop/new/flask-grinberg/venv/lib/python3.8/site-packages/flask/app.py", line 1503, in dispatch_request
    return self.ensure_sync(self.view_functions[rule.endpoint])(**req.view_args)
  File "/home/smr/Desktop/new/flask-grinberg/venv/lib/python3.8/site-packages/flask_login/utils.py", line 290, in decorated_view
    return current_app.ensure_sync(func)(*args, **kwargs)
  File "/home/smr/Desktop/new/flask-grinberg/myapp/routes.py", line 36, in index
    return render_template("index.html", title="Home", posts=myposts)
  File "/home/smr/Desktop/new/flask-grinberg/venv/lib/python3.8/site-packages/flask/templating.py", line 154, in render_template
    return _render(
  File "/home/smr/Desktop/new/flask-grinberg/venv/lib/python3.8/site-packages/flask/templating.py", line 128, in _render
    rv = template.render(context)
  File "/home/smr/Desktop/new/flask-grinberg/venv/lib/python3.8/site-packages/jinja2/environment.py", line 1301, in render
    self.environment.handle_exception()
  File "/home/smr/Desktop/new/flask-grinberg/venv/lib/python3.8/site-packages/jinja2/environment.py", line 936, in handle_exception
    raise rewrite_traceback_stack(source=source)
  File "/home/smr/Desktop/new/flask-grinberg/myapp/templates/index.html", line 1, in top-level template code
    {% extends "base.html" %}
  File "/home/smr/Desktop/new/flask-grinberg/myapp/templates/base.html", line 40, in top-level template code
    {% block content %}
  File "/home/smr/Desktop/new/flask-grinberg/myapp/templates/index.html", line 8, in block 'content'
    <p>{{ form.body.label }}</p>
  File "/home/smr/Desktop/new/flask-grinberg/venv/lib/python3.8/site-packages/jinja2/environment.py", line 485, in getattr
    return getattr(obj, attribute)
jinja2.exceptions.UndefinedError: 'form' is undefined
2022-08-03 02:15:25,050 INFO Microblog startup [in /home/smr/Desktop/new/flask-grinberg/myapp/logger.py:61]
